<sdf version='1.7'>
  <model name='px150'>
    <static>false</static>
    <joint name='fix_to_world' type='fixed'>
      <pose relative_to='__model__'>0 0 0 0 -0 0</pose>
      <parent>world</parent>
      <child>px150/base_link</child>
    </joint>
    <link name='px150/base_link'>
      <pose relative_to='fix_to_world'>0 0 0 0 -0 0</pose>
      <inertial>
        <pose>-0.035456 -0.003357 0.025342 0 -0 1.5708</pose>
        <mass>0.766173</mass>
        <inertia>
          <ixx>0.003355</ixx>
          <ixy>-0.0001248</ixy>
          <ixz>1.104e-05</ixz>
          <iyy>0.001357</iyy>
          <iyz>0.0002101</iyz>
          <izz>0.004112</izz>
        </inertia>
      </inertial>
      <collision name='px150/base_link_collision'>
        <pose>0 0 0 0 0 -1.5708</pose>
        <geometry>
          <mesh>
            <scale>0.001 0.001 0.001</scale>
            <uri>model://meshes/px150_meshes/px150_1_base_coll.stl</uri>
          </mesh>
        </geometry>
      </collision>
      <visual name='px150/base_link_visual'>
        <pose>0 0 0 0 0 -1.5708</pose>
        <geometry>
          <mesh>
            <scale>0.001 0.001 0.001</scale>
            <uri>model://meshes/px150_meshes/px150_1_base_coll.stl</uri>
          </mesh>
        </geometry>
      </visual>
    </link>
    <joint name='waist' type='revolute'>
      <pose relative_to='px150/base_link'>0 0 0.06566 0 -0 0</pose>
      <parent>px150/base_link</parent>
      <child>px150/shoulder_link</child>
      <axis>
        <xyz>0 0 1</xyz>
        <limit>
          <lower>-3.14158</lower>
          <upper>3.14158</upper>
          <effort>8</effort>
          <velocity>3.14159</velocity>
        </limit>
        <dynamics>
          <damping>0</damping>
          <friction>0.1</friction>
          <spring_reference>0</spring_reference>
          <spring_stiffness>0</spring_stiffness>
        </dynamics>
      </axis>
    </joint>
    <link name='px150/shoulder_link'>
      <pose relative_to='waist'>0 0 0 0 -0 0</pose>
      <inertial>
        <pose>-0.0001 2e-05 0.01041 0 -0 1.5708</pose>
        <mass>0.287601</mass>
        <inertia>
          <ixx>0.000239</ixx>
          <ixy>1e-09</ixy>
          <ixz>3.48e-08</ixz>
          <iyy>0.0003634</iyy>
          <iyz>3.613e-07</iyz>
          <izz>0.0004126</izz>
        </inertia>
      </inertial>
      <collision name='px150/shoulder_link_collision'>
        <pose>0 0 0.0015 0 0 -1.5708</pose>
        <geometry>
          <mesh>
            <scale>0.001 0.001 0.001</scale>
            <uri>model://meshes/px150_meshes/px150_2_shoulder_coll.stl</uri>
          </mesh>
        </geometry>
      </collision>
      <visual name='px150/shoulder_link_visual'>
        <pose>0 0 0.0015 0 0 -1.5708</pose>
        <geometry>
          <mesh>
            <scale>0.001 0.001 0.001</scale>
            <uri>model://meshes/px150_meshes/px150_2_shoulder_coll.stl</uri>
          </mesh>
        </geometry>
      </visual>
    </link>
    <joint name='shoulder' type='revolute'>
      <pose relative_to='px150/shoulder_link'>0 0 0.03891 0 -0 0</pose>
      <parent>px150/shoulder_link</parent>
      <child>px150/upper_arm_link</child>
      <axis>
        <xyz>0 1 0</xyz>
        <limit>
          <lower>-1.93732</lower>
          <upper>1.93732</upper>
          <effort>18</effort>
          <velocity>3.14159</velocity>
        </limit>
        <dynamics>
          <damping>0</damping>
          <friction>0.1</friction>
          <spring_reference>0</spring_reference>
          <spring_stiffness>0</spring_stiffness>
        </dynamics>
      </axis>
    </joint>
    <link name='px150/upper_arm_link'>
      <pose relative_to='shoulder'>0 0 0 0 -0 0</pose>
      <inertial>
        <pose>0.01661 0 0.115735 0 -0 1.5708</pose>
        <mass>0.338081</mass>
        <inertia>
          <ixx>0.001021</ixx>
          <ixy>-1e-10</ixy>
          <ixz>0</ixz>
          <iyy>0.001132</iyy>
          <iyz>0.0001839</iyz>
          <izz>0.0003525</izz>
        </inertia>
      </inertial>
      <collision name='px150/upper_arm_link_collision'>
        <pose>0 0 0 0 -0 1.5708</pose>
        <geometry>
          <mesh>
            <scale>0.001 0.001 0.001</scale>
            <uri>model://meshes/px150_meshes/px150_3_upper_arm_coll.stl</uri>
          </mesh>
        </geometry>
      </collision>
      <visual name='px150/upper_arm_link_visual'>
        <pose>0 0 0 0 -0 1.5708</pose>
        <geometry>
          <mesh>
            <scale>0.001 0.001 0.001</scale>
            <uri>model://meshes/px150_meshes/px150_3_upper_arm_coll.stl</uri>
          </mesh>
        </geometry>
      </visual>
    </link>
    <joint name='elbow' type='revolute'>
      <pose relative_to='px150/upper_arm_link'>0.05 0 0.15 0 -0 0</pose>
      <parent>px150/upper_arm_link</parent>
      <child>px150/forearm_link</child>
      <axis>
        <xyz>0 1 0</xyz>
        <limit>
          <lower>-2.0944</lower>
          <upper>1.65806</upper>
          <effort>13</effort>
          <velocity>3.14159</velocity>
        </limit>
        <dynamics>
          <damping>0</damping>
          <friction>0.1</friction>
          <spring_reference>0</spring_reference>
          <spring_stiffness>0</spring_stiffness>
        </dynamics>
      </axis>
    </joint>
    <link name='px150/forearm_link'>
      <pose relative_to='elbow'>0 0 0 0 -0 0</pose>
      <inertial>
        <pose>0.084847 -0.000107 0 0 -0 1.5708</pose>
        <mass>0.226542</mass>
        <inertia>
          <ixx>0.0005125</ixx>
          <ixy>-1.3403e-06</ixy>
          <ixz>0</ixz>
          <iyy>4.988e-05</iyy>
          <iyz>0</iyz>
          <izz>0.0005207</izz>
        </inertia>
      </inertial>
      <collision name='px150/forearm_link_collision'>
        <pose>0 0 0 0 -0 1.5708</pose>
        <geometry>
          <mesh>
            <scale>0.001 0.001 0.001</scale>
            <uri>model://meshes/px150_meshes/px150_4_forearm_coll.stl</uri>
          </mesh>
        </geometry>
      </collision>
      <visual name='px150/forearm_link_visual'>
        <pose>0 0 0 0 -0 1.5708</pose>
        <geometry>
          <mesh>
            <scale>0.001 0.001 0.001</scale>
            <uri>model://meshes/px150_meshes/px150_4_forearm_coll.stl</uri>
          </mesh>
        </geometry>
      </visual>
    </link>
    <joint name='wrist_angle' type='revolute'>
      <pose relative_to='px150/forearm_link'>0.15 0 0 0 -0 0</pose>
      <parent>px150/forearm_link</parent>
      <child>px150/wrist_link</child>
      <axis>
        <xyz>0 1 0</xyz>
        <limit>
          <lower>-1.74533</lower>
          <upper>2.14675</upper>
          <effort>5</effort>
          <velocity>3.14159</velocity>
        </limit>
        <dynamics>
          <damping>0</damping>
          <friction>0.1</friction>
          <spring_reference>0</spring_reference>
          <spring_stiffness>0</spring_stiffness>
        </dynamics>
      </axis>
    </joint>
    <link name='px150/wrist_link'>
      <pose relative_to='wrist_angle'>0 0 0 0 -0 0</pose>
      <inertial>
        <pose>0.04236 -1e-05 0.010577 0 -0 1.5708</pose>
        <mass>0.084957</mass>
        <inertia>
          <ixx>3.082e-05</ixx>
          <ixy>1.91e-08</ixy>
          <ixz>2.3e-09</ixz>
          <iyy>2.822e-05</iyy>
          <iyz>2.5481e-06</iyz>
          <izz>3.152e-05</izz>
        </inertia>
      </inertial>
      <collision name='px150/wrist_link_collision'>
        <pose>0 0 0 0 -0 1.5708</pose>
        <geometry>
          <mesh>
            <scale>0.001 0.001 0.001</scale>
            <uri>model://meshes/px150_meshes/px150_5_wrist_coll.stl</uri>
          </mesh>
        </geometry>
      </collision>
      <visual name='px150/wrist_link_visual'>
        <pose>0 0 0 0 -0 1.5708</pose>
        <geometry>
          <mesh>
            <scale>0.001 0.001 0.001</scale>
            <uri>model://meshes/px150_meshes/px150_5_wrist_coll.stl</uri>
          </mesh>
        </geometry>
      </visual>
    </link>
    <joint name='wrist_rotate' type='revolute'>
      <pose relative_to='px150/wrist_link'>0.065 0 0 0 -0 0</pose>
      <parent>px150/wrist_link</parent>
      <child>px150/gripper_link</child>
      <axis>
        <xyz>1 0 0</xyz>
        <limit>
          <lower>-3.14158</lower>
          <upper>3.14158</upper>
          <effort>1</effort>
          <velocity>3.14159</velocity>
        </limit>
        <dynamics>
          <damping>0</damping>
          <friction>0.1</friction>
          <spring_reference>0</spring_reference>
          <spring_stiffness>0</spring_stiffness>
        </dynamics>
      </axis>
    </joint>
    <link name='px150/gripper_link'>
      <pose relative_to='wrist_rotate'>0 0 0 0 -0 0</pose>
      <inertial>
        <pose>0.032529 0 0.009096 0 -0 1.5708</pose>
        <mass>0.110084</mass>
        <inertia>
          <ixx>0.000361516</ixx>
          <ixy>-4.09809e-10</ixy>
          <ixz>-5.19982e-10</ixz>
          <iyy>0.000348013</iyy>
          <iyz>-6.59796e-06</iyz>
          <izz>0.000372851</izz>
        </inertia>
      </inertial>
      <collision name='px150/gripper_link_collision'>
        <pose>-0.02 0 0 0 -0 1.5708</pose>
        <geometry>
          <mesh>
            <scale>0.001 0.001 0.001</scale>
            <uri>model://meshes/px150_meshes/px150_6_gripper_coll.stl</uri>
          </mesh>
        </geometry>
      </collision>
      <collision name='px150/gripper_link_fixed_joint_lump__px150/gripper_bar_link_collision_1'>
        <pose>-0.02 0 0 0 -0 1.5708</pose>
        <geometry>
          <mesh>
            <scale>0.001 0.001 0.001</scale>
            <uri>model://meshes/px150_meshes/px150_8_gripper_bar_coll.stl</uri>
          </mesh>
        </geometry>
      </collision>
      <visual name='px150/gripper_link_visual'>
        <pose>-0.02 0 0 0 -0 1.5708</pose>
        <geometry>
          <mesh>
            <scale>0.001 0.001 0.001</scale>
            <uri>model://meshes/px150_meshes/px150_6_gripper_coll.stl</uri>
          </mesh>
        </geometry>
      </visual>
      <visual name='px150/gripper_link_fixed_joint_lump__px150/gripper_bar_link_visual_1'>
        <pose>-0.02 0 0 0 -0 1.5708</pose>
        <geometry>
          <mesh>
            <scale>0.001 0.001 0.001</scale>
            <uri>model://meshes/px150_meshes/px150_8_gripper_bar_coll.stl</uri>
          </mesh>
        </geometry>
      </visual>
    </link>
    <joint name='gripper' type='revolute'>
      <pose relative_to='px150/gripper_link'>0.0485 0 0 0 -0 0</pose>
      <parent>px150/gripper_link</parent>
      <child>px150/gripper_prop_link</child>
      <axis>
        <xyz>1 0 0</xyz>
        <limit>
          <lower>-1e+16</lower>
          <upper>1e+16</upper>
        </limit>
        <dynamics>
          <damping>0</damping>
          <friction>0.1</friction>
          <spring_reference>0</spring_reference>
          <spring_stiffness>0</spring_stiffness>
        </dynamics>
      </axis>
    </joint>
    <link name='px150/gripper_prop_link'>
      <pose relative_to='gripper'>0 0 0 0 -0 0</pose>
      <inertial>
        <pose>0.000846 -2e-06 4.2e-05 0 -0 1.5708</pose>
        <mass>0.00434</mass>
        <inertia>
          <ixx>5.923e-07</ixx>
          <ixy>0</ixy>
          <ixz>3.195e-07</ixz>
          <iyy>1.1156e-06</iyy>
          <iyz>-4e-10</iyz>
          <izz>5.743e-07</izz>
        </inertia>
      </inertial>
      <collision name='px150/gripper_prop_link_collision'>
        <pose>-0.0685 0 0 0 -0 1.5708</pose>
        <geometry>
          <mesh>
            <scale>0.001 0.001 0.001</scale>
            <uri>model://meshes/px150_meshes/px150_7_gripper_prop_coll.stl</uri>
          </mesh>
        </geometry>
      </collision>
      <visual name='px150/gripper_prop_link_visual'>
        <pose>-0.0685 0 0 0 -0 1.5708</pose>
        <geometry>
          <mesh>
            <scale>0.001 0.001 0.001</scale>
            <uri>model://meshes/px150_meshes/px150_7_gripper_prop_coll.stl</uri>
          </mesh>
        </geometry>
      </visual>
    </link>
    <joint name='left_finger' type='prismatic'>
      <pose relative_to='px150/gripper_link'>0.066 0 0 0 -0 0</pose>
      <parent>px150/gripper_link</parent>
      <child>px150/left_finger_link</child>
      <axis>
        <xyz>0 1 0</xyz>
        <limit>
          <lower>0.015</lower>
          <upper>0.037</upper>
          <effort>5</effort>
          <velocity>1</velocity>
        </limit>
        <dynamics>
          <damping>0</damping>
          <friction>0.1</friction>
          <spring_reference>0</spring_reference>
          <spring_stiffness>0</spring_stiffness>
        </dynamics>
      </axis>
    </joint>
    <link name='px150/left_finger_link'>
      <pose relative_to='left_finger'>0 0 0 0 -0 0</pose>
      <inertial>
        <pose>0.013816 0 0 -0 0 -1.5708</pose>
        <mass>0.016246</mass>
        <inertia>
          <ixx>4.731e-06</ixx>
          <ixy>-4.56e-07</ixy>
          <ixz>0</ixz>
          <iyy>1.5506e-06</iyy>
          <iyz>0</iyz>
          <izz>3.7467e-06</izz>
        </inertia>
      </inertial>
      <collision name='px150/left_finger_link_collision'>
        <pose>0 0.005 0 -0 0 3.14159</pose>
        <geometry>
          <mesh>
            <scale>0.001 0.001 0.001</scale>
            <uri>model://meshes/px150_meshes/px150_9_gripper_finger_coll.stl</uri>
          </mesh>
        </geometry>
      </collision>
      <visual name='px150/left_finger_link_visual'>
        <pose>0 0.005 0 -0 0 3.14159</pose>
        <geometry>
          <mesh>
            <scale>0.001 0.001 0.001</scale>
            <uri>model://meshes/px150_meshes/px150_9_gripper_finger_coll.stl</uri>
          </mesh>
        </geometry>
      </visual>
    </link>
    <joint name='right_finger' type='prismatic'>
      <pose relative_to='px150/gripper_link'>0.066 0 0 0 -0 0</pose>
      <parent>px150/gripper_link</parent>
      <child>px150/right_finger_link</child>
      <axis>
        <xyz>0 1 0</xyz>
        <limit>
          <lower>-0.037</lower>
          <upper>-0.015</upper>
          <effort>5</effort>
          <velocity>1</velocity>
        </limit>
        <dynamics>
          <damping>0</damping>
          <friction>0.1</friction>
          <spring_reference>0</spring_reference>
          <spring_stiffness>0</spring_stiffness>
        </dynamics>
      </axis>
    </joint>
    <link name='px150/right_finger_link'>
      <pose relative_to='right_finger'>0 0 0 0 -0 0</pose>
      <inertial>
        <pose>0.013816 0 0 3.14159 0 -1.5708</pose>
        <mass>0.016246</mass>
        <inertia>
          <ixx>4.731e-06</ixx>
          <ixy>4.56e-07</ixy>
          <ixz>0</ixz>
          <iyy>1.5506e-06</iyy>
          <iyz>0</iyz>
          <izz>3.7467e-06</izz>
        </inertia>
      </inertial>
      <collision name='px150/right_finger_link_collision'>
        <pose>0 -0.005 0 3.14159 0 3.14159</pose>
        <geometry>
          <mesh>
            <scale>0.001 0.001 0.001</scale>
            <uri>model://meshes/px150_meshes/px150_9_gripper_finger_coll.stl</uri>
          </mesh>
        </geometry>
      </collision>
      <visual name='px150/right_finger_link_visual'>
        <pose>0 -0.005 0 3.14159 0 3.14159</pose>
        <geometry>
          <mesh>
            <scale>0.001 0.001 0.001</scale>
            <uri>model://meshes/px150_meshes/px150_9_gripper_finger_coll.stl</uri>
          </mesh>
        </geometry>
      </visual>
    </link>
  </model>
</sdf>
